Workbook
Name Societe: 'Accueil'!$C$6
Name Exercice: 'Accueil'!$C$12
Name Comptes: 'Plan comptable'!$H$8:$H$192
Name Journaux: 'Plan comptable'!$M$8:$M$13
Name Centres: 'Centres de coûts'!$A$8:$A$57

Sheet Accueil
A1: SYSTÈME COMPTABLE — SCF ALGÉRIE
A2: نظام محاسبي — النظام المحاسبي المالي الجزائري
A3: Plan comptable · Journal · Grand livre · Balance · Coût des ventes · Compte de résultat · Bilan
B5: IDENTIFICATION DE L'ENTREPRISE — تعريف المؤسسة
B6: Raison sociale | C6: Mon Entreprise SARL | E6: التسمية الاجتماعية
B7: NIF | E7: رقم التعريف الجبائي
B8: NIS | E8: رقم التعريف الإحصائي
B9: Registre de commerce | E9: السجل التجاري
B10: Article d'imposition | E10: المادة الجبائية
B11: Adresse | E11: العنوان
B12: Exercice | C12: 2026 | E12: السنة المالية
B13: Début d'exercice | C13: =DATE(Exercice,1,1) | E13: بداية السنة
B14: Fin d'exercice | C14: =DATE(Exercice,12,31) | E14: نهاية السنة
B16: LES FEUILLES — أوراق العمل
B17: → Plan comptable | D17: دليل الحسابات | E17: La nomenclature du SCF, classes 1 à 7, et vos propres subdivisions.
B18: → Centres de coûts | D18: مراكز التكلفة | E18: Magasin, chantier, véhicule : ce que vous voulez suivre à part.
B19: → Journal | D19: اليومية | E19: La seule feuille où l'on saisit. Une ligne par compte mouvementé.
B20: → Grand livre | D20: الأستاذ العام | E20: Le détail d'un compte, avec son solde qui court.
B21: → Balance | D21: ميزان المراجعة | E21: Mouvements et soldes de tous les comptes. Le contrôle d'équilibre.
B22: → Coût des ventes | D22: تكلفة المبيعات | E22: Ce que les ventes ont coûté, et ce qu'elles ont laissé.
B23: → Compte de résultat | D23: حساب النتائج | E23: Le compte de résultat par nature, avec ses soldes intermédiaires.
B24: → Bilan | D24: الميزانية | E24: Actif et passif à la clôture, présentation de l'arrêté de 2008.
B25: → Rapports | D25: التقارير | E25: TVA, trésorerie, tiers, charges par nature, résultat par centre.
B27: CONTRÔLES — المراقبة
B28: Total débit du journal | C28: =SUM('Journal'!$H$8:$H$2007)
B29: Total crédit du journal | C29: =SUM('Journal'!$I$8:$I$2007)
B30: Écart débit / crédit | C30: =SUM('Journal'!$H$8:$H$2007)-SUM('Journal'!$I$8:$I$2007)
B31: Résultat net de l'exercice | C31: ='Compte de résultat'!$D$36
B32: Total actif | C32: ='Bilan'!$E$29
B33: Total passif | C33: ='Bilan'!$E$53
B34: Écart actif / passif | C34: ='Bilan'!$E$29-'Bilan'!$E$53
B35: Le classeur est-il cohérent ? | C35: =IF(AND(ROUND(C30,2)=0,ROUND(C34,2)=0),"OUI — débit = crédit et actif = passif","NON — corrigez les écarts ci-dessus")
B37: MODE D'EMPLOI — طريقة الاستعمال
B38: 1. Renseignez l'entreprise et l'exercice ci-dessus. Tout le classeur en reprend le nom et l'année.
B39: 2. Ouvrez le Journal et saisissez vos écritures : une ligne par compte mouvementé, le débit à gauche, le crédit à droite. Le compte se choisit dans la liste déroulante.
B40: 3. Une écriture est équilibrée quand son débit égale son crédit. Le total du journal, en haut de la feuille, le dit à chaque instant.
B41: 4. Les dix lignes marquées EXEMPLE montrent une ouverture, une vente, un achat, un salaire, un amortissement et une déclaration de TVA. Supprimez-les avant de commencer.
B42: 5. Tout le reste se calcule seul. Aucune autre feuille n'attend de saisie, sauf les cellules jaunes du Coût des ventes.
B43: 6. Le plan comptable est modifiable : ajoutez vos subdivisions à la suite du tableau (4111 pour un client suivi à part, 6131 pour un local précis) et recopiez la formule des colonnes de droite.

Sheet Plan comptable
A1: PLAN COMPTABLE — SCF
A2: دليل الحسابات — النظام المحاسبي المالي
A3: =Societe&" · Exercice "&Exercice
A5: Arrêté du 26 juillet 2008. Les lignes grises sont des rubriques : on n'y passe pas d'écriture.
H6: Liste de saisie — ne pas trier ni supprimer
A7: Compte | B7: Intitulé | C7: التسمية | D7: Classe | E7: Type | F7: Rubrique du bilan | H7: Compte | I7: Intitulé | J7: Rubrique | K7: Déd. | M7: Journal | N7: Libellé
A8: 10 | B8: Capital, réserves et assimilés | C8: رأس المال والاحتياطات وما شابهها | D8: 1 | E8: Rubrique | H8: 101 | I8: Capital émis (capital social, fonds de dotation) | J8: CP_CAP | K8: 0 | M8: AN | N8: À-nouveaux
A9: 101 | B9: Capital émis (capital social, fonds de dotation) | C9: رأس المال الصادر (رأس المال الاجتماعي) | D9: 1 | E9: Compte | F9: CP_CAP | H9: 103 | I9: Primes liées au capital social | J9: CP_PRI | K9: 0 | M9: VE | N9: Ventes
A10: 103 | B10: Primes liées au capital social | C10: العلاوات المرتبطة برأس المال | D10: 1 | E10: Compte | F10: CP_PRI | H10: 104 | I10: Écart d'évaluation | J10: CP_PRI | K10: 0 | M10: AC | N10: Achats
A11: 104 | B11: Écart d'évaluation | C11: فارق التقييم | D11: 1 | E11: Compte | F11: CP_PRI | H11: 105 | I11: Écart de réévaluation | J11: CP_REE | K11: 0 | M11: BQ | N11: Banque
A12: 105 | B12: Écart de réévaluation | C12: فارق إعادة التقييم | D12: 1 | E12: Compte | F12: CP_REE | H12: 106 | I12: Réserves (légale, statutaire, ordinaire, réglementée) | J12: CP_PRI | K12: 0 | M12: CA | N12: Caisse
A13: 106 | B13: Réserves (légale, statutaire, ordinaire, réglementée) | C13: الاحتياطات (قانونية، نظامية، عادية، منظمة) | D13: 1 | E13: Compte | F13: CP_PRI | H13: 107 | I13: Écart d'équivalence | J13: CP_EQU | K13: 0 | M13: OD | N13: Opérations diverses
A14: 107 | B14: Écart d'équivalence | C14: فارق المعادلة | D14: 1 | E14: Compte | F14: CP_EQU | H14: 108 | I14: Compte de l'exploitant | J14: CP_ART | K14: 0
A15: 108 | B15: Compte de l'exploitant | C15: حساب المستغل | D15: 1 | E15: Compte | F15: CP_ART | H15: 109 | I15: Capital souscrit non appelé | J15: CP_NAP | K15: 0
A16: 109 | B16: Capital souscrit non appelé | C16: رأس المال المكتتب غير المستدعى | D16: 1 | E16: Compte | F16: CP_NAP | H16: 110 | I16: Report à nouveau (solde créditeur) | J16: CP_ART | K16: 0
A17: 11 | B17: Report à nouveau | C17: الترحيل من جديد | D17: 1 | E17: Rubrique | H17: 119 | I17: Report à nouveau (solde débiteur) | J17: CP_ART | K17: 0
A18: 110 | B18: Report à nouveau (solde créditeur) | C18: الترحيل من جديد (رصيد دائن) | D18: 1 | E18: Compte | F18: CP_ART | H18: 120 | I18: Résultat de l'exercice (bénéfice) | J18: CP_RES | K18: 0
A19: 119 | B19: Report à nouveau (solde débiteur) | C19: الترحيل من جديد (رصيد مدين) | D19: 1 | E19: Compte | F19: CP_ART | H19: 129 | I19: Résultat de l'exercice (perte) | J19: CP_RES | K19: 0
A20: 12 | B20: Résultat de l'exercice | C20: نتيجة السنة المالية | D20: 1 | E20: Rubrique | H20: 131 | I20: Subventions d'équipement | J20: PN_AUT | K20: 0
A21: 120 | B21: Résultat de l'exercice (bénéfice) | C21: نتيجة السنة المالية (ربح) | D21: 1 | E21: Compte | F21: CP_RES | H21: 133 | I21: Impôts différés actif | J21: AN_IDA | K21: 0
A22: 129 | B22: Résultat de l'exercice (perte) | C22: نتيجة السنة المالية (خسارة) | D22: 1 | E22: Compte | F22: CP_RES | H22: 134 | I22: Impôts différés passif | J22: PN_IDP | K22: 0
A23: 13 | B23: Produits et charges différés | C23: المنتوجات والأعباء المؤجلة | D23: 1 | E23: Rubrique | H23: 138 | I23: Autres produits et charges différés | J23: PN_AUT | K23: 0
A24: 131 | B24: Subventions d'équipement | C24: إعانات التجهيز | D24: 1 | E24: Compte | F24: PN_AUT | H24: 153 | I24: Provisions pour pensions et obligations similaires | J24: PN_PRO | K24: 0
A25: 133 | B25: Impôts différés actif | C25: الضرائب المؤجلة على الأصول | D25: 1 | E25: Compte | F25: AN_IDA | H25: 155 | I25: Provisions pour impôts | J25: PN_IDP | K25: 0
A26: 134 | B26: Impôts différés passif | C26: الضرائب المؤجلة على الخصوم | D26: 1 | E26: Compte | F26: PN_IDP | H26: 156 | I26: Provisions pour renouvellement des immobilisations | J26: PN_PRO | K26: 0
A27: 138 | B27: Autres produits et charges différés | C27: منتوجات وأعباء مؤجلة أخرى | D27: 1 | E27: Compte | F27: PN_AUT | H27: 158 | I27: Autres provisions pour charges | J27: PN_PRO | K27: 0
A28: 15 | B28: Provisions pour charges — passifs non courants | C28: مؤونات الأعباء — خصوم غير جارية | D28: 1 | E28: Rubrique | H28: 161 | I28: Titres participatifs | J28: PN_EMP | K28: 0
A29: 153 | B29: Provisions pour pensions et obligations similaires | C29: مؤونات المعاشات والالتزامات المماثلة | D29: 1 | E29: Compte | F29: PN_PRO | H29: 163 | I29: Autres emprunts obligataires | J29: PN_EMP | K29: 0
A30: 155 | B30: Provisions pour impôts | C30: مؤونات الضرائب | D30: 1 | E30: Compte | F30: PN_IDP | H30: 164 | I30: Emprunts auprès des établissements de crédit | J30: PN_EMP | K30: 0
A31: 156 | B31: Provisions pour renouvellement des immobilisations | C31: مؤونات تجديد التثبيتات | D31: 1 | E31: Compte | F31: PN_PRO | H31: 165 | I31: Dépôts et cautionnements reçus | J31: PN_AUT | K31: 0
A32: 158 | B32: Autres provisions pour charges | C32: مؤونات أخرى للأعباء | D32: 1 | E32: Compte | F32: PN_PRO | H32: 167 | I32: Dettes sur contrat de location-financement | J32: PN_EMP | K32: 0
A33: 16 | B33: Emprunts et dettes assimilées | C33: الاقتراضات والديون المماثلة | D33: 1 | E33: Rubrique | H33: 168 | I33: Autres emprunts et dettes assimilées | J33: PN_EMP | K33: 0
A34: 161 | B34: Titres participatifs | C34: سندات المساهمة | D34: 1 | E34: Compte | F34: PN_EMP | H34: 17 | I34: Dettes rattachées à des participations | J34: PN_EMP | K34: 0
A35: 163 | B35: Autres emprunts obligataires | C35: اقتراضات سندية أخرى | D35: 1 | E35: Compte | F35: PN_EMP | H35: 203 | I35: Frais de développement immobilisables | J35: AN_INC | K35: 0
A36: 164 | B36: Emprunts auprès des établissements de crédit | C36: الاقتراضات لدى مؤسسات القرض | D36: 1 | E36: Compte | F36: PN_EMP | H36: 204 | I36: Logiciels informatiques et assimilés | J36: AN_INC | K36: 0
A37: 165 | B37: Dépôts et cautionnements reçus | C37: الودائع والكفالات المقبوضة | D37: 1 | E37: Compte | F37: PN_AUT | H37: 205 | I37: Concessions, brevets, licences, marques | J37: AN_INC | K37: 0
A38: 167 | B38: Dettes sur contrat de location-financement | C38: ديون عقد الإيجار التمويلي | D38: 1 | E38: Compte | F38: PN_EMP | H38: 207 | I38: Écart d'acquisition (goodwill) | J38: AN_GW | K38: 0
A39: 168 | B39: Autres emprunts et dettes assimilées | C39: اقتراضات وديون مماثلة أخرى | D39: 1 | E39: Compte | F39: PN_EMP | H39: 208 | I39: Autres immobilisations incorporelles | J39: AN_INC | K39: 0
A40: 17 | B40: Dettes rattachées à des participations | C40: الديون الملحقة بمساهمات | D40: 1 | E40: Compte | F40: PN_EMP | H40: 211 | I40: Terrains | J40: AN_TER | K40: 0
A41: 20 | B41: Immobilisations incorporelles | C41: التثبيتات المعنوية | D41: 2 | E41: Rubrique | H41: 212 | I41: Agencements et aménagements de terrain | J41: AN_AUT | K41: 0
...

Sheet Centres de coûts
A1: CENTRES DE COÛTS
A2: مراكز التكلفة
A3: =Societe&" · Exercice "&Exercice
A5: Un centre s'affecte sur une ligne du journal, colonne G. Les charges et les produits qui le portent se retrouvent dans Rapports.
A7: Code | B7: Libellé | C7: التسمية | D7: Note
A8: MAG1 | B8: Magasin centre | C8: المحل المركزي | D8: EXEMPLE
A9: CH01 | B9: Chantier Alger | C9: ورشة الجزائر | D9: EXEMPLE
A10: VEH1 | B10: Véhicule utilitaire | C10: سيارة النفعية | D10: EXEMPLE

Sheet Journal
A1: JOURNAL GÉNÉRAL
A2: اليومية العامة
A3: =Societe&" · Exercice "&Exercice
A5: Une ligne par compte mouvementé. Un montant en débit OU en crédit, jamais les deux. La colonne Contrôle signale ce qui cloche.
A6: TOTAUX | H6: =SUM(H8:H2007) | I6: =SUM(I8:I2007) | J6: =IF(ROUND($H$6-$I$6,2)=0,"Équilibré","Écart : "&TEXT($H$6-$I$6,"#,##0.00"))
A7: Date | B7: Journal | C7: N° pièce | D7: Compte | E7: Intitulé du compte | F7: Libellé de l'opération | G7: Centre | H7: Débit | I7: Crédit | J7: Contrôle
A8: 46023 | B8: AN | C8: AN-2026 | D8: 2183 | E8: =IF($D8="","",IFERROR(VLOOKUP($D8,'Plan comptable'!$H:$I,2,FALSE),"compte hors plan")) | F8: Matériel informatique · EXEMPLE | H8: 80000 | J8: =IF($D8="","",IF(AND($H8<>"",$I8<>""),"débit ET crédit",IF(AND($H8="",$I8=""),"montant manquant",IF(ISNA(MATCH($D8,'Plan comptable'!$H:$H,0)),"compte hors plan",IF(AND($A8<>"",YEAR($A8)<>Exercice),"hors exercice","")))))
A9: 46023 | B9: AN | C9: AN-2026 | D9: 30 | E9: =IF($D9="","",IFERROR(VLOOKUP($D9,'Plan comptable'!$H:$I,2,FALSE),"compte hors plan")) | F9: Stock de marchandises au 01/01 · EXEMPLE | H9: 300000 | J9: =IF($D9="","",IF(AND($H9<>"",$I9<>""),"débit ET crédit",IF(AND($H9="",$I9=""),"montant manquant",IF(ISNA(MATCH($D9,'Plan comptable'!$H:$H,0)),"compte hors plan",IF(AND($A9<>"",YEAR($A9)<>Exercice),"hors exercice","")))))
A10: 46023 | B10: AN | C10: AN-2026 | D10: 512 | E10: =IF($D10="","",IFERROR(VLOOKUP($D10,'Plan comptable'!$H:$I,2,FALSE),"compte hors plan")) | F10: Solde bancaire au 01/01 · EXEMPLE | H10: 120000 | J10: =IF($D10="","",IF(AND($H10<>"",$I10<>""),"débit ET crédit",IF(AND($H10="",$I10=""),"montant manquant",IF(ISNA(MATCH($D10,'Plan comptable'!$H:$H,0)),"compte hors plan",IF(AND($A10<>"",YEAR($A10)<>Exercice),"hors exercice","")))))
A11: 46023 | B11: AN | C11: AN-2026 | D11: 101 | E11: =IF($D11="","",IFERROR(VLOOKUP($D11,'Plan comptable'!$H:$I,2,FALSE),"compte hors plan")) | F11: Capital · EXEMPLE | I11: 500000 | J11: =IF($D11="","",IF(AND($H11<>"",$I11<>""),"débit ET crédit",IF(AND($H11="",$I11=""),"montant manquant",IF(ISNA(MATCH($D11,'Plan comptable'!$H:$H,0)),"compte hors plan",IF(AND($A11<>"",YEAR($A11)<>Exercice),"hors exercice","")))))
A12: 46027 | B12: VE | C12: FAC-2026-001 | D12: 411 | E12: =IF($D12="","",IFERROR(VLOOKUP($D12,'Plan comptable'!$H:$I,2,FALSE),"compte hors plan")) | F12: SARL Atlas — facture 001 · EXEMPLE | G12: MAG1 | H12: 119000 | J12: =IF($D12="","",IF(AND($H12<>"",$I12<>""),"débit ET crédit",IF(AND($H12="",$I12=""),"montant manquant",IF(ISNA(MATCH($D12,'Plan comptable'!$H:$H,0)),"compte hors plan",IF(AND($A12<>"",YEAR($A12)<>Exercice),"hors exercice","")))))
A13: 46027 | B13: VE | C13: FAC-2026-001 | D13: 700 | E13: =IF($D13="","",IFERROR(VLOOKUP($D13,'Plan comptable'!$H:$I,2,FALSE),"compte hors plan")) | F13: Vente de marchandises · EXEMPLE | G13: MAG1 | I13: 100000 | J13: =IF($D13="","",IF(AND($H13<>"",$I13<>""),"débit ET crédit",IF(AND($H13="",$I13=""),"montant manquant",IF(ISNA(MATCH($D13,'Plan comptable'!$H:$H,0)),"compte hors plan",IF(AND($A13<>"",YEAR($A13)<>Exercice),"hors exercice","")))))
A14: 46027 | B14: VE | C14: FAC-2026-001 | D14: 4457 | E14: =IF($D14="","",IFERROR(VLOOKUP($D14,'Plan comptable'!$H:$I,2,FALSE),"compte hors plan")) | F14: TVA collectée 19 % · EXEMPLE | G14: MAG1 | I14: 19000 | J14: =IF($D14="","",IF(AND($H14<>"",$I14<>""),"débit ET crédit",IF(AND($H14="",$I14=""),"montant manquant",IF(ISNA(MATCH($D14,'Plan comptable'!$H:$H,0)),"compte hors plan",IF(AND($A14<>"",YEAR($A14)<>Exercice),"hors exercice","")))))
A15: 46042 | B15: BQ | C15: REG-001 | D15: 512 | E15: =IF($D15="","",IFERROR(VLOOKUP($D15,'Plan comptable'!$H:$I,2,FALSE),"compte hors plan")) | F15: Virement reçu — facture 001 · EXEMPLE | H15: 119000 | J15: =IF($D15="","",IF(AND($H15<>"",$I15<>""),"débit ET crédit",IF(AND($H15="",$I15=""),"montant manquant",IF(ISNA(MATCH($D15,'Plan comptable'!$H:$H,0)),"compte hors plan",IF(AND($A15<>"",YEAR($A15)<>Exercice),"hors exercice","")))))
A16: 46042 | B16: BQ | C16: REG-001 | D16: 411 | E16: =IF($D16="","",IFERROR(VLOOKUP($D16,'Plan comptable'!$H:$I,2,FALSE),"compte hors plan")) | F16: SARL Atlas · EXEMPLE | I16: 119000 | J16: =IF($D16="","",IF(AND($H16<>"",$I16<>""),"débit ET crédit",IF(AND($H16="",$I16=""),"montant manquant",IF(ISNA(MATCH($D16,'Plan comptable'!$H:$H,0)),"compte hors plan",IF(AND($A16<>"",YEAR($A16)<>Exercice),"hors exercice","")))))
A17: 46029 | B17: AC | C17: FA-FRS-014 | D17: 600 | E17: =IF($D17="","",IFERROR(VLOOKUP($D17,'Plan comptable'!$H:$I,2,FALSE),"compte hors plan")) | F17: Achat de marchandises · EXEMPLE | G17: MAG1 | H17: 60000 | J17: =IF($D17="","",IF(AND($H17<>"",$I17<>""),"débit ET crédit",IF(AND($H17="",$I17=""),"montant manquant",IF(ISNA(MATCH($D17,'Plan comptable'!$H:$H,0)),"compte hors plan",IF(AND($A17<>"",YEAR($A17)<>Exercice),"hors exercice","")))))
A18: 46029 | B18: AC | C18: FA-FRS-014 | D18: 44566 | E18: =IF($D18="","",IFERROR(VLOOKUP($D18,'Plan comptable'!$H:$I,2,FALSE),"compte hors plan")) | F18: TVA déductible 19 % · EXEMPLE | G18: MAG1 | H18: 11400 | J18: =IF($D18="","",IF(AND($H18<>"",$I18<>""),"débit ET crédit",IF(AND($H18="",$I18=""),"montant manquant",IF(ISNA(MATCH($D18,'Plan comptable'!$H:$H,0)),"compte hors plan",IF(AND($A18<>"",YEAR($A18)<>Exercice),"hors exercice","")))))
A19: 46029 | B19: AC | C19: FA-FRS-014 | D19: 401 | E19: =IF($D19="","",IFERROR(VLOOKUP($D19,'Plan comptable'!$H:$I,2,FALSE),"compte hors plan")) | F19: Fournisseur Sahara · EXEMPLE | G19: MAG1 | I19: 71400 | J19: =IF($D19="","",IF(AND($H19<>"",$I19<>""),"débit ET crédit",IF(AND($H19="",$I19=""),"montant manquant",IF(ISNA(MATCH($D19,'Plan comptable'!$H:$H,0)),"compte hors plan",IF(AND($A19<>"",YEAR($A19)<>Exercice),"hors exercice","")))))
A20: 46047 | B20: BQ | C20: REG-002 | D20: 401 | E20: =IF($D20="","",IFERROR(VLOOKUP($D20,'Plan comptable'!$H:$I,2,FALSE),"compte hors plan")) | F20: Règlement fournisseur Sahara · EXEMPLE | H20: 71400 | J20: =IF($D20="","",IF(AND($H20<>"",$I20<>""),"débit ET crédit",IF(AND($H20="",$I20=""),"montant manquant",IF(ISNA(MATCH($D20,'Plan comptable'!$H:$H,0)),"compte hors plan",IF(AND($A20<>"",YEAR($A20)<>Exercice),"hors exercice","")))))
A21: 46047 | B21: BQ | C21: REG-002 | D21: 512 | E21: =IF($D21="","",IFERROR(VLOOKUP($D21,'Plan comptable'!$H:$I,2,FALSE),"compte hors plan")) | F21: Virement émis · EXEMPLE | I21: 71400 | J21: =IF($D21="","",IF(AND($H21<>"",$I21<>""),"débit ET crédit",IF(AND($H21="",$I21=""),"montant manquant",IF(ISNA(MATCH($D21,'Plan comptable'!$H:$H,0)),"compte hors plan",IF(AND($A21<>"",YEAR($A21)<>Exercice),"hors exercice","")))))
A22: 46053 | B22: AC | C22: LOY-01 | D22: 613 | E22: =IF($D22="","",IFERROR(VLOOKUP($D22,'Plan comptable'!$H:$I,2,FALSE),"compte hors plan")) | F22: Loyer du local — janvier · EXEMPLE | G22: MAG1 | H22: 25000 | J22: =IF($D22="","",IF(AND($H22<>"",$I22<>""),"débit ET crédit",IF(AND($H22="",$I22=""),"montant manquant",IF(ISNA(MATCH($D22,'Plan comptable'!$H:$H,0)),"compte hors plan",IF(AND($A22<>"",YEAR($A22)<>Exercice),"hors exercice","")))))
A23: 46053 | B23: AC | C23: LOY-01 | D23: 512 | E23: =IF($D23="","",IFERROR(VLOOKUP($D23,'Plan comptable'!$H:$I,2,FALSE),"compte hors plan")) | F23: Loyer du local — janvier · EXEMPLE | G23: MAG1 | I23: 25000 | J23: =IF($D23="","",IF(AND($H23<>"",$I23<>""),"débit ET crédit",IF(AND($H23="",$I23=""),"montant manquant",IF(ISNA(MATCH($D23,'Plan comptable'!$H:$H,0)),"compte hors plan",IF(AND($A23<>"",YEAR($A23)<>Exercice),"hors exercice","")))))
A24: 46053 | B24: OD | C24: PAIE-01 | D24: 631 | E24: =IF($D24="","",IFERROR(VLOOKUP($D24,'Plan comptable'!$H:$I,2,FALSE),"compte hors plan")) | F24: Salaires de janvier · EXEMPLE | G24: MAG1 | H24: 45000 | J24: =IF($D24="","",IF(AND($H24<>"",$I24<>""),"débit ET crédit",IF(AND($H24="",$I24=""),"montant manquant",IF(ISNA(MATCH($D24,'Plan comptable'!$H:$H,0)),"compte hors plan",IF(AND($A24<>"",YEAR($A24)<>Exercice),"hors exercice","")))))
A25: 46053 | B25: OD | C25: PAIE-01 | D25: 431 | E25: =IF($D25="","",IFERROR(VLOOKUP($D25,'Plan comptable'!$H:$I,2,FALSE),"compte hors plan")) | F25: CNAS part salariale · EXEMPLE | G25: MAG1 | I25: 9000 | J25: =IF($D25="","",IF(AND($H25<>"",$I25<>""),"débit ET crédit",IF(AND($H25="",$I25=""),"montant manquant",IF(ISNA(MATCH($D25,'Plan comptable'!$H:$H,0)),"compte hors plan",IF(AND($A25<>"",YEAR($A25)<>Exercice),"hors exercice","")))))
A26: 46053 | B26: OD | C26: PAIE-01 | D26: 421 | E26: =IF($D26="","",IFERROR(VLOOKUP($D26,'Plan comptable'!$H:$I,2,FALSE),"compte hors plan")) | F26: Net à payer au personnel · EXEMPLE | G26: MAG1 | I26: 36000 | J26: =IF($D26="","",IF(AND($H26<>"",$I26<>""),"débit ET crédit",IF(AND($H26="",$I26=""),"montant manquant",IF(ISNA(MATCH($D26,'Plan comptable'!$H:$H,0)),"compte hors plan",IF(AND($A26<>"",YEAR($A26)<>Exercice),"hors exercice","")))))
A27: 46056 | B27: CA | C27: TICKET-02 | D27: 530 | E27: =IF($D27="","",IFERROR(VLOOKUP($D27,'Plan comptable'!$H:$I,2,FALSE),"compte hors plan")) | F27: Vente au comptant · EXEMPLE | G27: MAG1 | H27: 23800 | J27: =IF($D27="","",IF(AND($H27<>"",$I27<>""),"débit ET crédit",IF(AND($H27="",$I27=""),"montant manquant",IF(ISNA(MATCH($D27,'Plan comptable'!$H:$H,0)),"compte hors plan",IF(AND($A27<>"",YEAR($A27)<>Exercice),"hors exercice","")))))
A28: 46056 | B28: CA | C28: TICKET-02 | D28: 700 | E28: =IF($D28="","",IFERROR(VLOOKUP($D28,'Plan comptable'!$H:$I,2,FALSE),"compte hors plan")) | F28: Vente de marchandises · EXEMPLE | G28: MAG1 | I28: 20000 | J28: =IF($D28="","",IF(AND($H28<>"",$I28<>""),"débit ET crédit",IF(AND($H28="",$I28=""),"montant manquant",IF(ISNA(MATCH($D28,'Plan comptable'!$H:$H,0)),"compte hors plan",IF(AND($A28<>"",YEAR($A28)<>Exercice),"hors exercice","")))))
A29: 46056 | B29: CA | C29: TICKET-02 | D29: 4457 | E29: =IF($D29="","",IFERROR(VLOOKUP($D29,'Plan comptable'!$H:$I,2,FALSE),"compte hors plan")) | F29: TVA collectée 19 % · EXEMPLE | G29: MAG1 | I29: 3800 | J29: =IF($D29="","",IF(AND($H29<>"",$I29<>""),"débit ET crédit",IF(AND($H29="",$I29=""),"montant manquant",IF(ISNA(MATCH($D29,'Plan comptable'!$H:$H,0)),"compte hors plan",IF(AND($A29<>"",YEAR($A29)<>Exercice),"hors exercice","")))))
A30: 46081 | B30: OD | C30: AMORT-02 | D30: 681 | E30: =IF($D30="","",IFERROR(VLOOKUP($D30,'Plan comptable'!$H:$I,2,FALSE),"compte hors plan")) | F30: Dotation aux amortissements · EXEMPLE | H30: 1600 | J30: =IF($D30="","",IF(AND($H30<>"",$I30<>""),"débit ET crédit",IF(AND($H30="",$I30=""),"montant manquant",IF(ISNA(MATCH($D30,'Plan comptable'!$H:$H,0)),"compte hors plan",IF(AND($A30<>"",YEAR($A30)<>Exercice),"hors exercice","")))))
A31: 46081 | B31: OD | C31: AMORT-02 | D31: 281 | E31: =IF($D31="","",IFERROR(VLOOKUP($D31,'Plan comptable'!$H:$I,2,FALSE),"compte hors plan")) | F31: Amortissement du matériel · EXEMPLE | I31: 1600 | J31: =IF($D31="","",IF(AND($H31<>"",$I31<>""),"débit ET crédit",IF(AND($H31="",$I31=""),"montant manquant",IF(ISNA(MATCH($D31,'Plan comptable'!$H:$H,0)),"compte hors plan",IF(AND($A31<>"",YEAR($A31)<>Exercice),"hors exercice","")))))
A32: 46112 | B32: OD | C32: TVA-03 | D32: 4457 | E32: =IF($D32="","",IFERROR(VLOOKUP($D32,'Plan comptable'!$H:$I,2,FALSE),"compte hors plan")) | F32: TVA collectée du trimestre · EXEMPLE | H32: 22800 | J32: =IF($D32="","",IF(AND($H32<>"",$I32<>""),"débit ET crédit",IF(AND($H32="",$I32=""),"montant manquant",IF(ISNA(MATCH($D32,'Plan comptable'!$H:$H,0)),"compte hors plan",IF(AND($A32<>"",YEAR($A32)<>Exercice),"hors exercice","")))))
A33: 46112 | B33: OD | C33: TVA-03 | D33: 44566 | E33: =IF($D33="","",IFERROR(VLOOKUP($D33,'Plan comptable'!$H:$I,2,FALSE),"compte hors plan")) | F33: TVA déductible du trimestre · EXEMPLE | I33: 11400 | J33: =IF($D33="","",IF(AND($H33<>"",$I33<>""),"débit ET crédit",IF(AND($H33="",$I33=""),"montant manquant",IF(ISNA(MATCH($D33,'Plan comptable'!$H:$H,0)),"compte hors plan",IF(AND($A33<>"",YEAR($A33)<>Exercice),"hors exercice","")))))
A34: 46112 | B34: OD | C34: TVA-03 | D34: 4459 | E34: =IF($D34="","",IFERROR(VLOOKUP($D34,'Plan comptable'!$H:$I,2,FALSE),"compte hors plan")) | F34: TVA à décaisser · EXEMPLE | I34: 11400 | J34: =IF($D34="","",IF(AND($H34<>"",$I34<>""),"débit ET crédit",IF(AND($H34="",$I34=""),"montant manquant",IF(ISNA(MATCH($D34,'Plan comptable'!$H:$H,0)),"compte hors plan",IF(AND($A34<>"",YEAR($A34)<>Exercice),"hors exercice","")))))
E35: =IF($D35="","",IFERROR(VLOOKUP($D35,'Plan comptable'!$H:$I,2,FALSE),"compte hors plan")) | J35: =IF($D35="","",IF(AND($H35<>"",$I35<>""),"débit ET crédit",IF(AND($H35="",$I35=""),"montant manquant",IF(ISNA(MATCH($D35,'Plan comptable'!$H:$H,0)),"compte hors plan",IF(AND($A35<>"",YEAR($A35)<>Exercice),"hors exercice","")))))
E36: =IF($D36="","",IFERROR(VLOOKUP($D36,'Plan comptable'!$H:$I,2,FALSE),"compte hors plan")) | J36: =IF($D36="","",IF(AND($H36<>"",$I36<>""),"débit ET crédit",IF(AND($H36="",$I36=""),"montant manquant",IF(ISNA(MATCH($D36,'Plan comptable'!$H:$H,0)),"compte hors plan",IF(AND($A36<>"",YEAR($A36)<>Exercice),"hors exercice","")))))
E37: =IF($D37="","",IFERROR(VLOOKUP($D37,'Plan comptable'!$H:$I,2,FALSE),"compte hors plan")) | J37: =IF($D37="","",IF(AND($H37<>"",$I37<>""),"débit ET crédit",IF(AND($H37="",$I37=""),"montant manquant",IF(ISNA(MATCH($D37,'Plan comptable'!$H:$H,0)),"compte hors plan",IF(AND($A37<>"",YEAR($A37)<>Exercice),"hors exercice","")))))
E38: =IF($D38="","",IFERROR(VLOOKUP($D38,'Plan comptable'!$H:$I,2,FALSE),"compte hors plan")) | J38: =IF($D38="","",IF(AND($H38<>"",$I38<>""),"débit ET crédit",IF(AND($H38="",$I38=""),"montant manquant",IF(ISNA(MATCH($D38,'Plan comptable'!$H:$H,0)),"compte hors plan",IF(AND($A38<>"",YEAR($A38)<>Exercice),"hors exercice","")))))
E39: =IF($D39="","",IFERROR(VLOOKUP($D39,'Plan comptable'!$H:$I,2,FALSE),"compte hors plan")) | J39: =IF($D39="","",IF(AND($H39<>"",$I39<>""),"débit ET crédit",IF(AND($H39="",$I39=""),"montant manquant",IF(ISNA(MATCH($D39,'Plan comptable'!$H:$H,0)),"compte hors plan",IF(AND($A39<>"",YEAR($A39)<>Exercice),"hors exercice","")))))
E40: =IF($D40="","",IFERROR(VLOOKUP($D40,'Plan comptable'!$H:$I,2,FALSE),"compte hors plan")) | J40: =IF($D40="","",IF(AND($H40<>"",$I40<>""),"débit ET crédit",IF(AND($H40="",$I40=""),"montant manquant",IF(ISNA(MATCH($D40,'Plan comptable'!$H:$H,0)),"compte hors plan",IF(AND($A40<>"",YEAR($A40)<>Exercice),"hors exercice","")))))
E41: =IF($D41="","",IFERROR(VLOOKUP($D41,'Plan comptable'!$H:$I,2,FALSE),"compte hors plan")) | J41: =IF($D41="","",IF(AND($H41<>"",$I41<>""),"débit ET crédit",IF(AND($H41="",$I41=""),"montant manquant",IF(ISNA(MATCH($D41,'Plan comptable'!$H:$H,0)),"compte hors plan",IF(AND($A41<>"",YEAR($A41)<>Exercice),"hors exercice","")))))
...

Sheet Grand livre
A1: GRAND LIVRE
A2: الأستاذ العام
A3: =Societe&" · Exercice "&Exercice
A5: Compte : | C5: 411 | D5: =IFERROR(VLOOKUP($C$5,'Plan comptable'!$H:$I,2,FALSE),"—") | H5: choisissez un compte en C5
D6: Totaux du compte | E6: =SUMIF('Journal'!$D$8:$D$2007,$C$5,'Journal'!$H$8:$H$2007) | F6: =SUMIF('Journal'!$D$8:$D$2007,$C$5,'Journal'!$I$8:$I$2007) | G6: =$E$6-$F$6
A7: Date | B7: Journal | C7: N° pièce | D7: Libellé | E7: Débit | F7: Crédit | G7: Solde cumulé | H7: réf. (technique)
A8: =IF($H8="","",INDEX('Journal'!$A$8:$A$2007,$H8)) | B8: =IF($H8="","",INDEX('Journal'!$B$8:$B$2007,$H8)) | C8: =IF($H8="","",INDEX('Journal'!$C$8:$C$2007,$H8)) | D8: =IF($H8="","",INDEX('Journal'!$F$8:$F$2007,$H8)) | E8: =IF($H8="","",INDEX('Journal'!$H$8:$H$2007,$H8)) | F8: =IF($H8="","",INDEX('Journal'!$I$8:$I$2007,$H8)) | G8: =IF($H8="","",N(G7)+N(E8)-N(F8)) | H8: {=IFERROR(SMALL(IF('Journal'!$D$8:$D$2007=$C$5,ROW('Journal'!$D$8:$D$2007)-7),1),"")}
A9: =IF($H9="","",INDEX('Journal'!$A$8:$A$2007,$H9)) | B9: =IF($H9="","",INDEX('Journal'!$B$8:$B$2007,$H9)) | C9: =IF($H9="","",INDEX('Journal'!$C$8:$C$2007,$H9)) | D9: =IF($H9="","",INDEX('Journal'!$F$8:$F$2007,$H9)) | E9: =IF($H9="","",INDEX('Journal'!$H$8:$H$2007,$H9)) | F9: =IF($H9="","",INDEX('Journal'!$I$8:$I$2007,$H9)) | G9: =IF($H9="","",N(G8)+N(E9)-N(F9)) | H9: {=IFERROR(SMALL(IF('Journal'!$D$8:$D$2007=$C$5,ROW('Journal'!$D$8:$D$2007)-7),2),"")}
A10: =IF($H10="","",INDEX('Journal'!$A$8:$A$2007,$H10)) | B10: =IF($H10="","",INDEX('Journal'!$B$8:$B$2007,$H10)) | C10: =IF($H10="","",INDEX('Journal'!$C$8:$C$2007,$H10)) | D10: =IF($H10="","",INDEX('Journal'!$F$8:$F$2007,$H10)) | E10: =IF($H10="","",INDEX('Journal'!$H$8:$H$2007,$H10)) | F10: =IF($H10="","",INDEX('Journal'!$I$8:$I$2007,$H10)) | G10: =IF($H10="","",N(G9)+N(E10)-N(F10)) | H10: {=IFERROR(SMALL(IF('Journal'!$D$8:$D$2007=$C$5,ROW('Journal'!$D$8:$D$2007)-7),3),"")}
A11: =IF($H11="","",INDEX('Journal'!$A$8:$A$2007,$H11)) | B11: =IF($H11="","",INDEX('Journal'!$B$8:$B$2007,$H11)) | C11: =IF($H11="","",INDEX('Journal'!$C$8:$C$2007,$H11)) | D11: =IF($H11="","",INDEX('Journal'!$F$8:$F$2007,$H11)) | E11: =IF($H11="","",INDEX('Journal'!$H$8:$H$2007,$H11)) | F11: =IF($H11="","",INDEX('Journal'!$I$8:$I$2007,$H11)) | G11: =IF($H11="","",N(G10)+N(E11)-N(F11)) | H11: {=IFERROR(SMALL(IF('Journal'!$D$8:$D$2007=$C$5,ROW('Journal'!$D$8:$D$2007)-7),4),"")}
A12: =IF($H12="","",INDEX('Journal'!$A$8:$A$2007,$H12)) | B12: =IF($H12="","",INDEX('Journal'!$B$8:$B$2007,$H12)) | C12: =IF($H12="","",INDEX('Journal'!$C$8:$C$2007,$H12)) | D12: =IF($H12="","",INDEX('Journal'!$F$8:$F$2007,$H12)) | E12: =IF($H12="","",INDEX('Journal'!$H$8:$H$2007,$H12)) | F12: =IF($H12="","",INDEX('Journal'!$I$8:$I$2007,$H12)) | G12: =IF($H12="","",N(G11)+N(E12)-N(F12)) | H12: {=IFERROR(SMALL(IF('Journal'!$D$8:$D$2007=$C$5,ROW('Journal'!$D$8:$D$2007)-7),5),"")}
A13: =IF($H13="","",INDEX('Journal'!$A$8:$A$2007,$H13)) | B13: =IF($H13="","",INDEX('Journal'!$B$8:$B$2007,$H13)) | C13: =IF($H13="","",INDEX('Journal'!$C$8:$C$2007,$H13)) | D13: =IF($H13="","",INDEX('Journal'!$F$8:$F$2007,$H13)) | E13: =IF($H13="","",INDEX('Journal'!$H$8:$H$2007,$H13)) | F13: =IF($H13="","",INDEX('Journal'!$I$8:$I$2007,$H13)) | G13: =IF($H13="","",N(G12)+N(E13)-N(F13)) | H13: {=IFERROR(SMALL(IF('Journal'!$D$8:$D$2007=$C$5,ROW('Journal'!$D$8:$D$2007)-7),6),"")}
A14: =IF($H14="","",INDEX('Journal'!$A$8:$A$2007,$H14)) | B14: =IF($H14="","",INDEX('Journal'!$B$8:$B$2007,$H14)) | C14: =IF($H14="","",INDEX('Journal'!$C$8:$C$2007,$H14)) | D14: =IF($H14="","",INDEX('Journal'!$F$8:$F$2007,$H14)) | E14: =IF($H14="","",INDEX('Journal'!$H$8:$H$2007,$H14)) | F14: =IF($H14="","",INDEX('Journal'!$I$8:$I$2007,$H14)) | G14: =IF($H14="","",N(G13)+N(E14)-N(F14)) | H14: {=IFERROR(SMALL(IF('Journal'!$D$8:$D$2007=$C$5,ROW('Journal'!$D$8:$D$2007)-7),7),"")}
A15: =IF($H15="","",INDEX('Journal'!$A$8:$A$2007,$H15)) | B15: =IF($H15="","",INDEX('Journal'!$B$8:$B$2007,$H15)) | C15: =IF($H15="","",INDEX('Journal'!$C$8:$C$2007,$H15)) | D15: =IF($H15="","",INDEX('Journal'!$F$8:$F$2007,$H15)) | E15: =IF($H15="","",INDEX('Journal'!$H$8:$H$2007,$H15)) | F15: =IF($H15="","",INDEX('Journal'!$I$8:$I$2007,$H15)) | G15: =IF($H15="","",N(G14)+N(E15)-N(F15)) | H15: {=IFERROR(SMALL(IF('Journal'!$D$8:$D$2007=$C$5,ROW('Journal'!$D$8:$D$2007)-7),8),"")}
A16: =IF($H16="","",INDEX('Journal'!$A$8:$A$2007,$H16)) | B16: =IF($H16="","",INDEX('Journal'!$B$8:$B$2007,$H16)) | C16: =IF($H16="","",INDEX('Journal'!$C$8:$C$2007,$H16)) | D16: =IF($H16="","",INDEX('Journal'!$F$8:$F$2007,$H16)) | E16: =IF($H16="","",INDEX('Journal'!$H$8:$H$2007,$H16)) | F16: =IF($H16="","",INDEX('Journal'!$I$8:$I$2007,$H16)) | G16: =IF($H16="","",N(G15)+N(E16)-N(F16)) | H16: {=IFERROR(SMALL(IF('Journal'!$D$8:$D$2007=$C$5,ROW('Journal'!$D$8:$D$2007)-7),9),"")}
A17: =IF($H17="","",INDEX('Journal'!$A$8:$A$2007,$H17)) | B17: =IF($H17="","",INDEX('Journal'!$B$8:$B$2007,$H17)) | C17: =IF($H17="","",INDEX('Journal'!$C$8:$C$2007,$H17)) | D17: =IF($H17="","",INDEX('Journal'!$F$8:$F$2007,$H17)) | E17: =IF($H17="","",INDEX('Journal'!$H$8:$H$2007,$H17)) | F17: =IF($H17="","",INDEX('Journal'!$I$8:$I$2007,$H17)) | G17: =IF($H17="","",N(G16)+N(E17)-N(F17)) | H17: {=IFERROR(SMALL(IF('Journal'!$D$8:$D$2007=$C$5,ROW('Journal'!$D$8:$D$2007)-7),10),"")}
A18: =IF($H18="","",INDEX('Journal'!$A$8:$A$2007,$H18)) | B18: =IF($H18="","",INDEX('Journal'!$B$8:$B$2007,$H18)) | C18: =IF($H18="","",INDEX('Journal'!$C$8:$C$2007,$H18)) | D18: =IF($H18="","",INDEX('Journal'!$F$8:$F$2007,$H18)) | E18: =IF($H18="","",INDEX('Journal'!$H$8:$H$2007,$H18)) | F18: =IF($H18="","",INDEX('Journal'!$I$8:$I$2007,$H18)) | G18: =IF($H18="","",N(G17)+N(E18)-N(F18)) | H18: {=IFERROR(SMALL(IF('Journal'!$D$8:$D$2007=$C$5,ROW('Journal'!$D$8:$D$2007)-7),11),"")}
A19: =IF($H19="","",INDEX('Journal'!$A$8:$A$2007,$H19)) | B19: =IF($H19="","",INDEX('Journal'!$B$8:$B$2007,$H19)) | C19: =IF($H19="","",INDEX('Journal'!$C$8:$C$2007,$H19)) | D19: =IF($H19="","",INDEX('Journal'!$F$8:$F$2007,$H19)) | E19: =IF($H19="","",INDEX('Journal'!$H$8:$H$2007,$H19)) | F19: =IF($H19="","",INDEX('Journal'!$I$8:$I$2007,$H19)) | G19: =IF($H19="","",N(G18)+N(E19)-N(F19)) | H19: {=IFERROR(SMALL(IF('Journal'!$D$8:$D$2007=$C$5,ROW('Journal'!$D$8:$D$2007)-7),12),"")}
A20: =IF($H20="","",INDEX('Journal'!$A$8:$A$2007,$H20)) | B20: =IF($H20="","",INDEX('Journal'!$B$8:$B$2007,$H20)) | C20: =IF($H20="","",INDEX('Journal'!$C$8:$C$2007,$H20)) | D20: =IF($H20="","",INDEX('Journal'!$F$8:$F$2007,$H20)) | E20: =IF($H20="","",INDEX('Journal'!$H$8:$H$2007,$H20)) | F20: =IF($H20="","",INDEX('Journal'!$I$8:$I$2007,$H20)) | G20: =IF($H20="","",N(G19)+N(E20)-N(F20)) | H20: {=IFERROR(SMALL(IF('Journal'!$D$8:$D$2007=$C$5,ROW('Journal'!$D$8:$D$2007)-7),13),"")}
A21: =IF($H21="","",INDEX('Journal'!$A$8:$A$2007,$H21)) | B21: =IF($H21="","",INDEX('Journal'!$B$8:$B$2007,$H21)) | C21: =IF($H21="","",INDEX('Journal'!$C$8:$C$2007,$H21)) | D21: =IF($H21="","",INDEX('Journal'!$F$8:$F$2007,$H21)) | E21: =IF($H21="","",INDEX('Journal'!$H$8:$H$2007,$H21)) | F21: =IF($H21="","",INDEX('Journal'!$I$8:$I$2007,$H21)) | G21: =IF($H21="","",N(G20)+N(E21)-N(F21)) | H21: {=IFERROR(SMALL(IF('Journal'!$D$8:$D$2007=$C$5,ROW('Journal'!$D$8:$D$2007)-7),14),"")}
A22: =IF($H22="","",INDEX('Journal'!$A$8:$A$2007,$H22)) | B22: =IF($H22="","",INDEX('Journal'!$B$8:$B$2007,$H22)) | C22: =IF($H22="","",INDEX('Journal'!$C$8:$C$2007,$H22)) | D22: =IF($H22="","",INDEX('Journal'!$F$8:$F$2007,$H22)) | E22: =IF($H22="","",INDEX('Journal'!$H$8:$H$2007,$H22)) | F22: =IF($H22="","",INDEX('Journal'!$I$8:$I$2007,$H22)) | G22: =IF($H22="","",N(G21)+N(E22)-N(F22)) | H22: {=IFERROR(SMALL(IF('Journal'!$D$8:$D$2007=$C$5,ROW('Journal'!$D$8:$D$2007)-7),15),"")}
A23: =IF($H23="","",INDEX('Journal'!$A$8:$A$2007,$H23)) | B23: =IF($H23="","",INDEX('Journal'!$B$8:$B$2007,$H23)) | C23: =IF($H23="","",INDEX('Journal'!$C$8:$C$2007,$H23)) | D23: =IF($H23="","",INDEX('Journal'!$F$8:$F$2007,$H23)) | E23: =IF($H23="","",INDEX('Journal'!$H$8:$H$2007,$H23)) | F23: =IF($H23="","",INDEX('Journal'!$I$8:$I$2007,$H23)) | G23: =IF($H23="","",N(G22)+N(E23)-N(F23)) | H23: {=IFERROR(SMALL(IF('Journal'!$D$8:$D$2007=$C$5,ROW('Journal'!$D$8:$D$2007)-7),16),"")}
A24: =IF($H24="","",INDEX('Journal'!$A$8:$A$2007,$H24)) | B24: =IF($H24="","",INDEX('Journal'!$B$8:$B$2007,$H24)) | C24: =IF($H24="","",INDEX('Journal'!$C$8:$C$2007,$H24)) | D24: =IF($H24="","",INDEX('Journal'!$F$8:$F$2007,$H24)) | E24: =IF($H24="","",INDEX('Journal'!$H$8:$H$2007,$H24)) | F24: =IF($H24="","",INDEX('Journal'!$I$8:$I$2007,$H24)) | G24: =IF($H24="","",N(G23)+N(E24)-N(F24)) | H24: {=IFERROR(SMALL(IF('Journal'!$D$8:$D$2007=$C$5,ROW('Journal'!$D$8:$D$2007)-7),17),"")}
A25: =IF($H25="","",INDEX('Journal'!$A$8:$A$2007,$H25)) | B25: =IF($H25="","",INDEX('Journal'!$B$8:$B$2007,$H25)) | C25: =IF($H25="","",INDEX('Journal'!$C$8:$C$2007,$H25)) | D25: =IF($H25="","",INDEX('Journal'!$F$8:$F$2007,$H25)) | E25: =IF($H25="","",INDEX('Journal'!$H$8:$H$2007,$H25)) | F25: =IF($H25="","",INDEX('Journal'!$I$8:$I$2007,$H25)) | G25: =IF($H25="","",N(G24)+N(E25)-N(F25)) | H25: {=IFERROR(SMALL(IF('Journal'!$D$8:$D$2007=$C$5,ROW('Journal'!$D$8:$D$2007)-7),18),"")}
A26: =IF($H26="","",INDEX('Journal'!$A$8:$A$2007,$H26)) | B26: =IF($H26="","",INDEX('Journal'!$B$8:$B$2007,$H26)) | C26: =IF($H26="","",INDEX('Journal'!$C$8:$C$2007,$H26)) | D26: =IF($H26="","",INDEX('Journal'!$F$8:$F$2007,$H26)) | E26: =IF($H26="","",INDEX('Journal'!$H$8:$H$2007,$H26)) | F26: =IF($H26="","",INDEX('Journal'!$I$8:$I$2007,$H26)) | G26: =IF($H26="","",N(G25)+N(E26)-N(F26)) | H26: {=IFERROR(SMALL(IF('Journal'!$D$8:$D$2007=$C$5,ROW('Journal'!$D$8:$D$2007)-7),19),"")}
A27: =IF($H27="","",INDEX('Journal'!$A$8:$A$2007,$H27)) | B27: =IF($H27="","",INDEX('Journal'!$B$8:$B$2007,$H27)) | C27: =IF($H27="","",INDEX('Journal'!$C$8:$C$2007,$H27)) | D27: =IF($H27="","",INDEX('Journal'!$F$8:$F$2007,$H27)) | E27: =IF($H27="","",INDEX('Journal'!$H$8:$H$2007,$H27)) | F27: =IF($H27="","",INDEX('Journal'!$I$8:$I$2007,$H27)) | G27: =IF($H27="","",N(G26)+N(E27)-N(F27)) | H27: {=IFERROR(SMALL(IF('Journal'!$D$8:$D$2007=$C$5,ROW('Journal'!$D$8:$D$2007)-7),20),"")}
A28: =IF($H28="","",INDEX('Journal'!$A$8:$A$2007,$H28)) | B28: =IF($H28="","",INDEX('Journal'!$B$8:$B$2007,$H28)) | C28: =IF($H28="","",INDEX('Journal'!$C$8:$C$2007,$H28)) | D28: =IF($H28="","",INDEX('Journal'!$F$8:$F$2007,$H28)) | E28: =IF($H28="","",INDEX('Journal'!$H$8:$H$2007,$H28)) | F28: =IF($H28="","",INDEX('Journal'!$I$8:$I$2007,$H28)) | G28: =IF($H28="","",N(G27)+N(E28)-N(F28)) | H28: {=IFERROR(SMALL(IF('Journal'!$D$8:$D$2007=$C$5,ROW('Journal'!$D$8:$D$2007)-7),21),"")}
A29: =IF($H29="","",INDEX('Journal'!$A$8:$A$2007,$H29)) | B29: =IF($H29="","",INDEX('Journal'!$B$8:$B$2007,$H29)) | C29: =IF($H29="","",INDEX('Journal'!$C$8:$C$2007,$H29)) | D29: =IF($H29="","",INDEX('Journal'!$F$8:$F$2007,$H29)) | E29: =IF($H29="","",INDEX('Journal'!$H$8:$H$2007,$H29)) | F29: =IF($H29="","",INDEX('Journal'!$I$8:$I$2007,$H29)) | G29: =IF($H29="","",N(G28)+N(E29)-N(F29)) | H29: {=IFERROR(SMALL(IF('Journal'!$D$8:$D$2007=$C$5,ROW('Journal'!$D$8:$D$2007)-7),22),"")}
A30: =IF($H30="","",INDEX('Journal'!$A$8:$A$2007,$H30)) | B30: =IF($H30="","",INDEX('Journal'!$B$8:$B$2007,$H30)) | C30: =IF($H30="","",INDEX('Journal'!$C$8:$C$2007,$H30)) | D30: =IF($H30="","",INDEX('Journal'!$F$8:$F$2007,$H30)) | E30: =IF($H30="","",INDEX('Journal'!$H$8:$H$2007,$H30)) | F30: =IF($H30="","",INDEX('Journal'!$I$8:$I$2007,$H30)) | G30: =IF($H30="","",N(G29)+N(E30)-N(F30)) | H30: {=IFERROR(SMALL(IF('Journal'!$D$8:$D$2007=$C$5,ROW('Journal'!$D$8:$D$2007)-7),23),"")}
A31: =IF($H31="","",INDEX('Journal'!$A$8:$A$2007,$H31)) | B31: =IF($H31="","",INDEX('Journal'!$B$8:$B$2007,$H31)) | C31: =IF($H31="","",INDEX('Journal'!$C$8:$C$2007,$H31)) | D31: =IF($H31="","",INDEX('Journal'!$F$8:$F$2007,$H31)) | E31: =IF($H31="","",INDEX('Journal'!$H$8:$H$2007,$H31)) | F31: =IF($H31="","",INDEX('Journal'!$I$8:$I$2007,$H31)) | G31: =IF($H31="","",N(G30)+N(E31)-N(F31)) | H31: {=IFERROR(SMALL(IF('Journal'!$D$8:$D$2007=$C$5,ROW('Journal'!$D$8:$D$2007)-7),24),"")}
A32: =IF($H32="","",INDEX('Journal'!$A$8:$A$2007,$H32)) | B32: =IF($H32="","",INDEX('Journal'!$B$8:$B$2007,$H32)) | C32: =IF($H32="","",INDEX('Journal'!$C$8:$C$2007,$H32)) | D32: =IF($H32="","",INDEX('Journal'!$F$8:$F$2007,$H32)) | E32: =IF($H32="","",INDEX('Journal'!$H$8:$H$2007,$H32)) | F32: =IF($H32="","",INDEX('Journal'!$I$8:$I$2007,$H32)) | G32: =IF($H32="","",N(G31)+N(E32)-N(F32)) | H32: {=IFERROR(SMALL(IF('Journal'!$D$8:$D$2007=$C$5,ROW('Journal'!$D$8:$D$2007)-7),25),"")}
A33: =IF($H33="","",INDEX('Journal'!$A$8:$A$2007,$H33)) | B33: =IF($H33="","",INDEX('Journal'!$B$8:$B$2007,$H33)) | C33: =IF($H33="","",INDEX('Journal'!$C$8:$C$2007,$H33)) | D33: =IF($H33="","",INDEX('Journal'!$F$8:$F$2007,$H33)) | E33: =IF($H33="","",INDEX('Journal'!$H$8:$H$2007,$H33)) | F33: =IF($H33="","",INDEX('Journal'!$I$8:$I$2007,$H33)) | G33: =IF($H33="","",N(G32)+N(E33)-N(F33)) | H33: {=IFERROR(SMALL(IF('Journal'!$D$8:$D$2007=$C$5,ROW('Journal'!$D$8:$D$2007)-7),26),"")}
A34: =IF($H34="","",INDEX('Journal'!$A$8:$A$2007,$H34)) | B34: =IF($H34="","",INDEX('Journal'!$B$8:$B$2007,$H34)) | C34: =IF($H34="","",INDEX('Journal'!$C$8:$C$2007,$H34)) | D34: =IF($H34="","",INDEX('Journal'!$F$8:$F$2007,$H34)) | E34: =IF($H34="","",INDEX('Journal'!$H$8:$H$2007,$H34)) | F34: =IF($H34="","",INDEX('Journal'!$I$8:$I$2007,$H34)) | G34: =IF($H34="","",N(G33)+N(E34)-N(F34)) | H34: {=IFERROR(SMALL(IF('Journal'!$D$8:$D$2007=$C$5,ROW('Journal'!$D$8:$D$2007)-7),27),"")}
A35: =IF($H35="","",INDEX('Journal'!$A$8:$A$2007,$H35)) | B35: =IF($H35="","",INDEX('Journal'!$B$8:$B$2007,$H35)) | C35: =IF($H35="","",INDEX('Journal'!$C$8:$C$2007,$H35)) | D35: =IF($H35="","",INDEX('Journal'!$F$8:$F$2007,$H35)) | E35: =IF($H35="","",INDEX('Journal'!$H$8:$H$2007,$H35)) | F35: =IF($H35="","",INDEX('Journal'!$I$8:$I$2007,$H35)) | G35: =IF($H35="","",N(G34)+N(E35)-N(F35)) | H35: {=IFERROR(SMALL(IF('Journal'!$D$8:$D$2007=$C$5,ROW('Journal'!$D$8:$D$2007)-7),28),"")}
A36: =IF($H36="","",INDEX('Journal'!$A$8:$A$2007,$H36)) | B36: =IF($H36="","",INDEX('Journal'!$B$8:$B$2007,$H36)) | C36: =IF($H36="","",INDEX('Journal'!$C$8:$C$2007,$H36)) | D36: =IF($H36="","",INDEX('Journal'!$F$8:$F$2007,$H36)) | E36: =IF($H36="","",INDEX('Journal'!$H$8:$H$2007,$H36)) | F36: =IF($H36="","",INDEX('Journal'!$I$8:$I$2007,$H36)) | G36: =IF($H36="","",N(G35)+N(E36)-N(F36)) | H36: {=IFERROR(SMALL(IF('Journal'!$D$8:$D$2007=$C$5,ROW('Journal'!$D$8:$D$2007)-7),29),"")}
A37: =IF($H37="","",INDEX('Journal'!$A$8:$A$2007,$H37)) | B37: =IF($H37="","",INDEX('Journal'!$B$8:$B$2007,$H37)) | C37: =IF($H37="","",INDEX('Journal'!$C$8:$C$2007,$H37)) | D37: =IF($H37="","",INDEX('Journal'!$F$8:$F$2007,$H37)) | E37: =IF($H37="","",INDEX('Journal'!$H$8:$H$2007,$H37)) | F37: =IF($H37="","",INDEX('Journal'!$I$8:$I$2007,$H37)) | G37: =IF($H37="","",N(G36)+N(E37)-N(F37)) | H37: {=IFERROR(SMALL(IF('Journal'!$D$8:$D$2007=$C$5,ROW('Journal'!$D$8:$D$2007)-7),30),"")}
A38: =IF($H38="","",INDEX('Journal'!$A$8:$A$2007,$H38)) | B38: =IF($H38="","",INDEX('Journal'!$B$8:$B$2007,$H38)) | C38: =IF($H38="","",INDEX('Journal'!$C$8:$C$2007,$H38)) | D38: =IF($H38="","",INDEX('Journal'!$F$8:$F$2007,$H38)) | E38: =IF($H38="","",INDEX('Journal'!$H$8:$H$2007,$H38)) | F38: =IF($H38="","",INDEX('Journal'!$I$8:$I$2007,$H38)) | G38: =IF($H38="","",N(G37)+N(E38)-N(F38)) | H38: {=IFERROR(SMALL(IF('Journal'!$D$8:$D$2007=$C$5,ROW('Journal'!$D$8:$D$2007)-7),31),"")}
A39: =IF($H39="","",INDEX('Journal'!$A$8:$A$2007,$H39)) | B39: =IF($H39="","",INDEX('Journal'!$B$8:$B$2007,$H39)) | C39: =IF($H39="","",INDEX('Journal'!$C$8:$C$2007,$H39)) | D39: =IF($H39="","",INDEX('Journal'!$F$8:$F$2007,$H39)) | E39: =IF($H39="","",INDEX('Journal'!$H$8:$H$2007,$H39)) | F39: =IF($H39="","",INDEX('Journal'!$I$8:$I$2007,$H39)) | G39: =IF($H39="","",N(G38)+N(E39)-N(F39)) | H39: {=IFERROR(SMALL(IF('Journal'!$D$8:$D$2007=$C$5,ROW('Journal'!$D$8:$D$2007)-7),32),"")}
A40: =IF($H40="","",INDEX('Journal'!$A$8:$A$2007,$H40)) | B40: =IF($H40="","",INDEX('Journal'!$B$8:$B$2007,$H40)) | C40: =IF($H40="","",INDEX('Journal'!$C$8:$C$2007,$H40)) | D40: =IF($H40="","",INDEX('Journal'!$F$8:$F$2007,$H40)) | E40: =IF($H40="","",INDEX('Journal'!$H$8:$H$2007,$H40)) | F40: =IF($H40="","",INDEX('Journal'!$I$8:$I$2007,$H40)) | G40: =IF($H40="","",N(G39)+N(E40)-N(F40)) | H40: {=IFERROR(SMALL(IF('Journal'!$D$8:$D$2007=$C$5,ROW('Journal'!$D$8:$D$2007)-7),33),"")}
A41: =IF($H41="","",INDEX('Journal'!$A$8:$A$2007,$H41)) | B41: =IF($H41="","",INDEX('Journal'!$B$8:$B$2007,$H41)) | C41: =IF($H41="","",INDEX('Journal'!$C$8:$C$2007,$H41)) | D41: =IF($H41="","",INDEX('Journal'!$F$8:$F$2007,$H41)) | E41: =IF($H41="","",INDEX('Journal'!$H$8:$H$2007,$H41)) | F41: =IF($H41="","",INDEX('Journal'!$I$8:$I$2007,$H41)) | G41: =IF($H41="","",N(G40)+N(E41)-N(F41)) | H41: {=IFERROR(SMALL(IF('Journal'!$D$8:$D$2007=$C$5,ROW('Journal'!$D$8:$D$2007)-7),34),"")}
...

Sheet Balance
A1: BALANCE GÉNÉRALE
A2: ميزان المراجعة
A3: =Societe&" · Exercice "&Exercice
A5: =IF(ROUND(SUM(C8:C192)-SUM(D8:D192),2)=0,"Balance équilibrée : total débit = total crédit.","Balance déséquilibrée — écart de "&TEXT(SUM(C8:C192)-SUM(D8:D192),"#,##0.00")&" DA. Une écriture du journal ne se boucle pas.")
A7: Compte | B7: Intitulé | C7: Mouvement débit | D7: Mouvement crédit | E7: Solde débiteur | F7: Solde créditeur | G7: Solde signé | H7: Rubrique | I7: Déd. | J7: Cl. | K7: Préf. 2 | L7: Préf. 3
A8: 101 | B8: Capital émis (capital social, fonds de dotation) | C8: =SUMIF('Journal'!$D$8:$D$2007,$A8,'Journal'!$H$8:$H$2007) | D8: =SUMIF('Journal'!$D$8:$D$2007,$A8,'Journal'!$I$8:$I$2007) | E8: =IF($C8-$D8>0,$C8-$D8,0) | F8: =IF($D8-$C8>0,$D8-$C8,0) | G8: =$C8-$D8 | H8: CP_CAP | I8: 0 | J8: 1 | K8: 10 | L8: 101
A9: 103 | B9: Primes liées au capital social | C9: =SUMIF('Journal'!$D$8:$D$2007,$A9,'Journal'!$H$8:$H$2007) | D9: =SUMIF('Journal'!$D$8:$D$2007,$A9,'Journal'!$I$8:$I$2007) | E9: =IF($C9-$D9>0,$C9-$D9,0) | F9: =IF($D9-$C9>0,$D9-$C9,0) | G9: =$C9-$D9 | H9: CP_PRI | I9: 0 | J9: 1 | K9: 10 | L9: 103
A10: 104 | B10: Écart d'évaluation | C10: =SUMIF('Journal'!$D$8:$D$2007,$A10,'Journal'!$H$8:$H$2007) | D10: =SUMIF('Journal'!$D$8:$D$2007,$A10,'Journal'!$I$8:$I$2007) | E10: =IF($C10-$D10>0,$C10-$D10,0) | F10: =IF($D10-$C10>0,$D10-$C10,0) | G10: =$C10-$D10 | H10: CP_PRI | I10: 0 | J10: 1 | K10: 10 | L10: 104
A11: 105 | B11: Écart de réévaluation | C11: =SUMIF('Journal'!$D$8:$D$2007,$A11,'Journal'!$H$8:$H$2007) | D11: =SUMIF('Journal'!$D$8:$D$2007,$A11,'Journal'!$I$8:$I$2007) | E11: =IF($C11-$D11>0,$C11-$D11,0) | F11: =IF($D11-$C11>0,$D11-$C11,0) | G11: =$C11-$D11 | H11: CP_REE | I11: 0 | J11: 1 | K11: 10 | L11: 105
A12: 106 | B12: Réserves (légale, statutaire, ordinaire, réglementée) | C12: =SUMIF('Journal'!$D$8:$D$2007,$A12,'Journal'!$H$8:$H$2007) | D12: =SUMIF('Journal'!$D$8:$D$2007,$A12,'Journal'!$I$8:$I$2007) | E12: =IF($C12-$D12>0,$C12-$D12,0) | F12: =IF($D12-$C12>0,$D12-$C12,0) | G12: =$C12-$D12 | H12: CP_PRI | I12: 0 | J12: 1 | K12: 10 | L12: 106
A13: 107 | B13: Écart d'équivalence | C13: =SUMIF('Journal'!$D$8:$D$2007,$A13,'Journal'!$H$8:$H$2007) | D13: =SUMIF('Journal'!$D$8:$D$2007,$A13,'Journal'!$I$8:$I$2007) | E13: =IF($C13-$D13>0,$C13-$D13,0) | F13: =IF($D13-$C13>0,$D13-$C13,0) | G13: =$C13-$D13 | H13: CP_EQU | I13: 0 | J13: 1 | K13: 10 | L13: 107
A14: 108 | B14: Compte de l'exploitant | C14: =SUMIF('Journal'!$D$8:$D$2007,$A14,'Journal'!$H$8:$H$2007) | D14: =SUMIF('Journal'!$D$8:$D$2007,$A14,'Journal'!$I$8:$I$2007) | E14: =IF($C14-$D14>0,$C14-$D14,0) | F14: =IF($D14-$C14>0,$D14-$C14,0) | G14: =$C14-$D14 | H14: CP_ART | I14: 0 | J14: 1 | K14: 10 | L14: 108
A15: 109 | B15: Capital souscrit non appelé | C15: =SUMIF('Journal'!$D$8:$D$2007,$A15,'Journal'!$H$8:$H$2007) | D15: =SUMIF('Journal'!$D$8:$D$2007,$A15,'Journal'!$I$8:$I$2007) | E15: =IF($C15-$D15>0,$C15-$D15,0) | F15: =IF($D15-$C15>0,$D15-$C15,0) | G15: =$C15-$D15 | H15: CP_NAP | I15: 0 | J15: 1 | K15: 10 | L15: 109
A16: 110 | B16: Report à nouveau (solde créditeur) | C16: =SUMIF('Journal'!$D$8:$D$2007,$A16,'Journal'!$H$8:$H$2007) | D16: =SUMIF('Journal'!$D$8:$D$2007,$A16,'Journal'!$I$8:$I$2007) | E16: =IF($C16-$D16>0,$C16-$D16,0) | F16: =IF($D16-$C16>0,$D16-$C16,0) | G16: =$C16-$D16 | H16: CP_ART | I16: 0 | J16: 1 | K16: 11 | L16: 110
A17: 119 | B17: Report à nouveau (solde débiteur) | C17: =SUMIF('Journal'!$D$8:$D$2007,$A17,'Journal'!$H$8:$H$2007) | D17: =SUMIF('Journal'!$D$8:$D$2007,$A17,'Journal'!$I$8:$I$2007) | E17: =IF($C17-$D17>0,$C17-$D17,0) | F17: =IF($D17-$C17>0,$D17-$C17,0) | G17: =$C17-$D17 | H17: CP_ART | I17: 0 | J17: 1 | K17: 11 | L17: 119
A18: 120 | B18: Résultat de l'exercice (bénéfice) | C18: =SUMIF('Journal'!$D$8:$D$2007,$A18,'Journal'!$H$8:$H$2007) | D18: =SUMIF('Journal'!$D$8:$D$2007,$A18,'Journal'!$I$8:$I$2007) | E18: =IF($C18-$D18>0,$C18-$D18,0) | F18: =IF($D18-$C18>0,$D18-$C18,0) | G18: =$C18-$D18 | H18: CP_RES | I18: 0 | J18: 1 | K18: 12 | L18: 120
A19: 129 | B19: Résultat de l'exercice (perte) | C19: =SUMIF('Journal'!$D$8:$D$2007,$A19,'Journal'!$H$8:$H$2007) | D19: =SUMIF('Journal'!$D$8:$D$2007,$A19,'Journal'!$I$8:$I$2007) | E19: =IF($C19-$D19>0,$C19-$D19,0) | F19: =IF($D19-$C19>0,$D19-$C19,0) | G19: =$C19-$D19 | H19: CP_RES | I19: 0 | J19: 1 | K19: 12 | L19: 129
... A118: 59 | B118: Pertes de valeur sur actifs financiers courants | C118: =SUMIF('Journal'!$D$8:$D$2007,$A118,'Journal'!$H$8:$H$2007) | D118: =SUMIF('Journal'!$D$8:$D$2007,$A118,'Journal'!$I$8:$I$2007) | E118: =IF($C118-$D118>0,$C118-$D118,0) | F118: =IF($D118-$C118>0,$D118-$C118,0) | G118: =$C118-$D118 | H118: AC_PLA | I118: 1 | J118: 5 | K118: 59 | L118: 59
A119: 600 | B119: Achats de marchandises vendues | C119: =SUMIF('Journal'!$D$8:$D$2007,$A119,'Journal'!$H$8:$H$2007) | D119: =SUMIF('Journal'!$D$8:$D$2007,$A119,'Journal'!$I$8:$I$2007) | E119: =IF($C119-$D119>0,$C119-$D119,0) | F119: =IF($D119-$C119>0,$D119-$C119,0) | G119: =$C119-$D119 | I119: 0 | J119: 6 | K119: 60 | L119: 600
A120: 601 | B120: Matières premières | C120: =SUMIF('Journal'!$D$8:$D$2007,$A120,'Journal'!$H$8:$H$2007) | D120: =SUMIF('Journal'!$D$8:$D$2007,$A120,'Journal'!$I$8:$I$2007) | E120: =IF($C120-$D120>0,$C120-$D120,0) | F120: =IF($D120-$C120>0,$D120-$C120,0) | G120: =$C120-$D120 | I120: 0 | J120: 6 | K120: 60 | L120: 601
A121: 602 | B121: Autres approvisionnements | C121: =SUMIF('Journal'!$D$8:$D$2007,$A121,'Journal'!$H$8:$H$2007) | D121: =SUMIF('Journal'!$D$8:$D$2007,$A121,'Journal'!$I$8:$I$2007) | E121: =IF($C121-$D121>0,$C121-$D121,0) | F121: =IF($D121-$C121>0,$D121-$C121,0) | G121: =$C121-$D121 | I121: 0 | J121: 6 | K121: 60 | L121: 602
A122: 603 | B122: Variation des stocks | C122: =SUMIF('Journal'!$D$8:$D$2007,$A122,'Journal'!$H$8:$H$2007) | D122: =SUMIF('Journal'!$D$8:$D$2007,$A122,'Journal'!$I$8:$I$2007) | E122: =IF($C122-$D122>0,$C122-$D122,0) | F122: =IF($D122-$C122>0,$D122-$C122,0) | G122: =$C122-$D122 | I122: 0 | J122: 6 | K122: 60 | L122: 603
A123: 604 | B123: Achats d'études et de prestations de services | C123: =SUMIF('Journal'!$D$8:$D$2007,$A123,'Journal'!$H$8:$H$2007) | D123: =SUMIF('Journal'!$D$8:$D$2007,$A123,'Journal'!$I$8:$I$2007) | E123: =IF($C123-$D123>0,$C123-$D123,0) | F123: =IF($D123-$C123>0,$D123-$C123,0) | G123: =$C123-$D123 | I123: 0 | J123: 6 | K123: 60 | L123: 604
A124: 605 | B124: Achats de matériels, équipements et travaux | C124: =SUMIF('Journal'!$D$8:$D$2007,$A124,'Journal'!$H$8:$H$2007) | D124: =SUMIF('Journal'!$D$8:$D$2007,$A124,'Journal'!$I$8:$I$2007) | E124: =IF($C124-$D124>0,$C124-$D124,0) | F124: =IF($D124-$C124>0,$D124-$C124,0) | G124: =$C124-$D124 | I124: 0 | J124: 6 | K124: 60 | L124: 605
A125: 607 | B125: Achats non stockés de matières et fournitures | C125: =SUMIF('Journal'!$D$8:$D$2007,$A125,'Journal'!$H$8:$H$2007) | D125: =SUMIF('Journal'!$D$8:$D$2007,$A125,'Journal'!$I$8:$I$2007) | E125: =IF($C125-$D125>0,$C125-$D125,0) | F125: =IF($D125-$C125>0,$D125-$C125,0) | G125: =$C125-$D125 | I125: 0 | J125: 6 | K125: 60 | L125: 607
A126: 608 | B126: Frais accessoires d'achat | C126: =SUMIF('Journal'!$D$8:$D$2007,$A126,'Journal'!$H$8:$H$2007) | D126: =SUMIF('Journal'!$D$8:$D$2007,$A126,'Journal'!$I$8:$I$2007) | E126: =IF($C126-$D126>0,$C126-$D126,0) | F126: =IF($D126-$C126>0,$D126-$C126,0) | G126: =$C126-$D126 | I126: 0 | J126: 6 | K126: 60 | L126: 608
A127: 609 | B127: Rabais, remises et ristournes obtenus sur achats | C127: =SUMIF('Journal'!$D$8:$D$2007,$A127,'Journal'!$H$8:$H$2007) | D127: =SUMIF('Journal'!$D$8:$D$2007,$A127,'Journal'!$I$8:$I$2007) | E127: =IF($C127-$D127>0,$C127-$D127,0) | F127: =IF($D127-$C127>0,$D127-$C127,0) | G127: =$C127-$D127 | I127: 0 | J127: 6 | K127: 60 | L127: 609
A128: 611 | B128: Sous-traitance générale | C128: =SUMIF('Journal'!$D$8:$D$2007,$A128,'Journal'!$H$8:$H$2007) | D128: =SUMIF('Journal'!$D$8:$D$2007,$A128,'Journal'!$I$8:$I$2007) | E128: =IF($C128-$D128>0,$C128-$D128,0) | F128: =IF($D128-$C128>0,$D128-$C128,0) | G128: =$C128-$D128 | I128: 0 | J128: 6 | K128: 61 | L128: 611
A129: 613 | B129: Locations | C129: =SUMIF('Journal'!$D$8:$D$2007,$A129,'Journal'!$H$8:$H$2007) | D129: =SUMIF('Journal'!$D$8:$D$2007,$A129,'Journal'!$I$8:$I$2007) | E129: =IF($C129-$D129>0,$C129-$D129,0) | F129: =IF($D129-$C129>0,$D129-$C129,0) | G129: =$C129-$D129 | I129: 0 | J129: 6 | K129: 61 | L129: 613
A130: 614 | B130: Charges locatives et de copropriété | C130: =SUMIF('Journal'!$D$8:$D$2007,$A130,'Journal'!$H$8:$H$2007) | D130: =SUMIF('Journal'!$D$8:$D$2007,$A130,'Journal'!$I$8:$I$2007) | E130: =IF($C130-$D130>0,$C130-$D130,0) | F130: =IF($D130-$C130>0,$D130-$C130,0) | G130: =$C130-$D130 | I130: 0 | J130: 6 | K130: 61 | L130: 614
... A192: 786 | B192: Reprises — éléments financiers | C192: =SUMIF('Journal'!$D$8:$D$2007,$A192,'Journal'!$H$8:$H$2007) | D192: =SUMIF('Journal'!$D$8:$D$2007,$A192,'Journal'!$I$8:$I$2007) | E192: =IF($C192-$D192>0,$C192-$D192,0) | F192: =IF($D192-$C192>0,$D192-$C192,0) | G192: =$C192-$D192 | I192: 0 | J192: 7 | K192: 78 | L192: 786
A193: TOTAUX | C193: =SUM(C8:C192) | D193: =SUM(D8:D192) | E193: =SUM(E8:E192) | F193: =SUM(F8:F192) | G193: =SUM(G8:G192)
A194: Les six colonnes de droite servent au bilan et au compte de résultat. Elles ne se saisissent pas et ne se suppriment pas.

Sheet Coût des ventes
A1: COÛT DES VENTES ET MARGE
A2: تكلفة المبيعات والهامش
A3: =Societe&" · Exercice "&Exercice
A5: Deux lectures de la même chose. En haut, produit par produit, à partir de ce que vous saisissez ici. En bas, ce que disent les comptes du journal.
A7: PAR PRODUIT — حسب المنتج (cellules jaunes : à saisir)
A8: Désignation | B8: Quantité vendue | C8: Prix de vente HT | D8: Prix d'achat HT | E8: Ventes HT | F8: Coût d'achat | G8: Marge | H8: Taux
A9: Ciment CPJ 42.5 — sac 50 kg | B9: 400 | C9: 850 | D9: 620 | E9: =IF($A9="","",N($B9)*N($C9)) | F9: =IF($A9="","",N($B9)*N($D9)) | G9: =IF($A9="","",N($E9)-N($F9)) | H9: =IF(N($E9)=0,"",N($G9)/N($E9)*100)
A10: Rond à béton Ø10 — barre | B10: 120 | C10: 1250 | D10: 980 | E10: =IF($A10="","",N($B10)*N($C10)) | F10: =IF($A10="","",N($B10)*N($D10)) | G10: =IF($A10="","",N($E10)-N($F10)) | H10: =IF(N($E10)=0,"",N($G10)/N($E10)*100)
A11: Peinture intérieure — 20 L | B11: 35 | C11: 4200 | D11: 2950 | E11: =IF($A11="","",N($B11)*N($C11)) | F11: =IF($A11="","",N($B11)*N($D11)) | G11: =IF($A11="","",N($E11)-N($F11)) | H11: =IF(N($E11)=0,"",N($G11)/N($E11)*100)
E12: =IF($A12="","",N($B12)*N($C12)) | F12: =IF($A12="","",N($B12)*N($D12)) | G12: =IF($A12="","",N($E12)-N($F12)) | H12: =IF(N($E12)=0,"",N($G12)/N($E12)*100)
E13: =IF($A13="","",N($B13)*N($C13)) | F13: =IF($A13="","",N($B13)*N($D13)) | G13: =IF($A13="","",N($E13)-N($F13)) | H13: =IF(N($E13)=0,"",N($G13)/N($E13)*100)
E14: =IF($A14="","",N($B14)*N($C14)) | F14: =IF($A14="","",N($B14)*N($D14)) | G14: =IF($A14="","",N($E14)-N($F14)) | H14: =IF(N($E14)=0,"",N($G14)/N($E14)*100)
E15: =IF($A15="","",N($B15)*N($C15)) | F15: =IF($A15="","",N($B15)*N($D15)) | G15: =IF($A15="","",N($E15)-N($F15)) | H15: =IF(N($E15)=0,"",N($G15)/N($E15)*100)
E16: =IF($A16="","",N($B16)*N($C16)) | F16: =IF($A16="","",N($B16)*N($D16)) | G16: =IF($A16="","",N($E16)-N($F16)) | H16: =IF(N($E16)=0,"",N($G16)/N($E16)*100)
E17: =IF($A17="","",N($B17)*N($C17)) | F17: =IF($A17="","",N($B17)*N($D17)) | G17: =IF($A17="","",N($E17)-N($F17)) | H17: =IF(N($E17)=0,"",N($G17)/N($E17)*100)
E18: =IF($A18="","",N($B18)*N($C18)) | F18: =IF($A18="","",N($B18)*N($D18)) | G18: =IF($A18="","",N($E18)-N($F18)) | H18: =IF(N($E18)=0,"",N($G18)/N($E18)*100)
E19: =IF($A19="","",N($B19)*N($C19)) | F19: =IF($A19="","",N($B19)*N($D19)) | G19: =IF($A19="","",N($E19)-N($F19)) | H19: =IF(N($E19)=0,"",N($G19)/N($E19)*100)
E20: =IF($A20="","",N($B20)*N($C20)) | F20: =IF($A20="","",N($B20)*N($D20)) | G20: =IF($A20="","",N($E20)-N($F20)) | H20: =IF(N($E20)=0,"",N($G20)/N($E20)*100)
E21: =IF($A21="","",N($B21)*N($C21)) | F21: =IF($A21="","",N($B21)*N($D21)) | G21: =IF($A21="","",N($E21)-N($F21)) | H21: =IF(N($E21)=0,"",N($G21)/N($E21)*100)
E22: =IF($A22="","",N($B22)*N($C22)) | F22: =IF($A22="","",N($B22)*N($D22)) | G22: =IF($A22="","",N($E22)-N($F22)) | H22: =IF(N($E22)=0,"",N($G22)/N($E22)*100)
E23: =IF($A23="","",N($B23)*N($C23)) | F23: =IF($A23="","",N($B23)*N($D23)) | G23: =IF($A23="","",N($E23)-N($F23)) | H23: =IF(N($E23)=0,"",N($G23)/N($E23)*100)
... E38: =IF($A38="","",N($B38)*N($C38)) | F38: =IF($A38="","",N($B38)*N($D38)) | G38: =IF($A38="","",N($E38)-N($F38)) | H38: =IF(N($E38)=0,"",N($G38)/N($E38)*100)
A39: TOTAL | E39: =SUM(E9:E38) | F39: =SUM(F9:F38) | G39: =SUM(G9:G38) | H39: =IF($E39=0,"",$G39/$E39*100)
A41: CE QUE DISENT LES COMPTES — ما تقوله الحسابات
A42: Ventes de l'exercice (comptes 70) | C42: =-SUMIF('Balance'!$K$8:$K$192,"70",'Balance'!$G$8:$G$192)
A43: Stock initial de marchandises | C43: 300000
A44: Achats consommés (comptes 60) | C44: =SUMIF('Balance'!$K$8:$K$192,"60",'Balance'!$G$8:$G$192)
A45: Stock final de marchandises | C45: 260000
A46: Coût des marchandises vendues | C46: =N($C43)+N($C44)-N($C45)
A47: Marge brute | C47: =N($C42)-N($C46)
A48: Taux de marge | C48: =IF(N($C42)=0,"",N($C47)/N($C42)*100)
A50: Le SCF tient l'inventaire intermittent : le coût des marchandises vendues ne se constate pas vente par vente, il se déduit en fin d'exercice du stock initial, des achats et du stock final. Le tableau du haut est une estimation de gestion, celui du bas est le chiffre comptable. Les deux ne coïncident que si tout ce qui a été acheté a été vendu.

Sheet Compte de résultat
A1: COMPTE DE RÉSULTAT PAR NATURE
A2: حساب النتائج حسب الطبيعة
A3: =Societe&" · Exercice "&Exercice
A5: Présentation de l'arrêté du 26 juillet 2008, avec ses soldes intermédiaires de gestion.
B7: Rubrique | C7: التسمية | D7: Exercice
B8: Ventes et produits annexes | C8: المبيعات والمنتوجات الملحقة | D8: =-SUMIF('Balance'!$K$8:$K$192,"70",'Balance'!$G$8:$G$192)
B9: Variation stocks produits finis et en cours | C9: تغير مخزونات المنتجات التامة وقيد التنفيذ | D9: =-SUMIF('Balance'!$K$8:$K$192,"72",'Balance'!$G$8:$G$192)
B10: Production immobilisée | C10: الإنتاج المثبت | D10: =-SUMIF('Balance'!$K$8:$K$192,"73",'Balance'!$G$8:$G$192)
B11: Subventions d'exploitation | C11: إعانات الاستغلال | D11: =-SUMIF('Balance'!$K$8:$K$192,"74",'Balance'!$G$8:$G$192)
A12: I | B12: PRODUCTION DE L'EXERCICE | C12: إنتاج السنة المالية | D12: =SUM($D$8:$D$11)
B13: Achats consommés | C13: المشتريات المستهلكة | D13: =SUMIF('Balance'!$K$8:$K$192,"60",'Balance'!$G$8:$G$192)
B14: Services extérieurs et autres consommations | C14: الخدمات الخارجية والاستهلاكات الأخرى | D14: =SUMIF('Balance'!$K$8:$K$192,"61",'Balance'!$G$8:$G$192)+SUMIF('Balance'!$K$8:$K$192,"62",'Balance'!$G$8:$G$192)
A15: II | B15: CONSOMMATION DE L'EXERCICE | C15: استهلاكات السنة المالية | D15: =$D$13+$D$14
A16: III | B16: VALEUR AJOUTÉE D'EXPLOITATION | C16: القيمة المضافة للاستغلال | D16: =$D$12-$D$15
B17: Charges de personnel | C17: أعباء المستخدمين | D17: =SUMIF('Balance'!$K$8:$K$192,"63",'Balance'!$G$8:$G$192)
B18: Impôts, taxes et versements assimilés | C18: الضرائب والرسوم والمدفوعات المماثلة | D18: =SUMIF('Balance'!$K$8:$K$192,"64",'Balance'!$G$8:$G$192)
A19: IV | B19: EXCÉDENT BRUT D'EXPLOITATION | C19: الفائض الإجمالي عن الاستغلال | D19: =$D$16-$D$17-$D$18
B20: Autres produits opérationnels | C20: المنتوجات العملياتية الأخرى | D20: =-SUMIF('Balance'!$K$8:$K$192,"75",'Balance'!$G$8:$G$192)
B21: Autres charges opérationnelles | C21: الأعباء العملياتية الأخرى | D21: =SUMIF('Balance'!$K$8:$K$192,"65",'Balance'!$G$8:$G$192)
B22: Dotations aux amortissements, provisions et pertes de valeur | C22: مخصصات الاهتلاكات والمؤونات وخسائر القيمة | D22: =SUMIF('Balance'!$K$8:$K$192,"68",'Balance'!$G$8:$G$192)
B23: Reprise sur pertes de valeur et provisions | C23: استئناف خسائر القيمة والمؤونات | D23: =-SUMIF('Balance'!$K$8:$K$192,"78",'Balance'!$G$8:$G$192)
A24: V | B24: RÉSULTAT OPÉRATIONNEL | C24: النتيجة العملياتية | D24: =$D$19+$D$20-$D$21-$D$22+$D$23
B25: Produits financiers | C25: المنتوجات المالية | D25: =-SUMIF('Balance'!$K$8:$K$192,"76",'Balance'!$G$8:$G$192)
B26: Charges financières | C26: الأعباء المالية | D26: =SUMIF('Balance'!$K$8:$K$192,"66",'Balance'!$G$8:$G$192)
A27: VI | B27: RÉSULTAT FINANCIER | C27: النتيجة المالية | D27: =$D$25-$D$26
A28: VII | B28: RÉSULTAT ORDINAIRE AVANT IMPÔTS | C28: النتيجة العادية قبل الضرائب | D28: =$D$24+$D$27
B29: Impôts exigibles sur résultats ordinaires | C29: الضرائب الواجبة على النتائج العادية | D29: =SUMIF('Balance'!$L$8:$L$192,"695",'Balance'!$G$8:$G$192)+SUMIF('Balance'!$L$8:$L$192,"698",'Balance'!$G$8:$G$192)
B30: Impôts différés sur résultats ordinaires | C30: الضرائب المؤجلة على النتائج العادية | D30: =SUMIF('Balance'!$L$8:$L$192,"692",'Balance'!$G$8:$G$192)+SUMIF('Balance'!$L$8:$L$192,"693",'Balance'!$G$8:$G$192)
B31: TOTAL DES PRODUITS DES ACTIVITÉS ORDINAIRES | C31: مجموع منتوجات الأنشطة العادية | D31: =$D$8+$D$9+$D$10+$D$11+$D$20+$D$23+$D$25
B32: TOTAL DES CHARGES DES ACTIVITÉS ORDINAIRES | C32: مجموع أعباء الأنشطة العادية | D32: =$D$13+$D$14+$D$17+$D$18+$D$21+$D$22+$D$26+$D$29+$D$30
A33: VIII | B33: RÉSULTAT NET DES ACTIVITÉS ORDINAIRES | C33: النتيجة الصافية للأنشطة العادية | D33: =$D$31-$D$32
B34: Éléments extraordinaires — produits | C34: العناصر غير العادية — منتوجات | D34: =-SUMIF('Balance'!$K$8:$K$192,"77",'Balance'!$G$8:$G$192)
B35: Éléments extraordinaires — charges | C35: العناصر غير العادية — أعباء | D35: =SUMIF('Balance'!$K$8:$K$192,"67",'Balance'!$G$8:$G$192)
A36: IX | B36: RÉSULTAT NET DE L'EXERCICE | C36: النتيجة الصافية للسنة المالية | D36: =$D$33+$D$34-$D$35
